Workbook
Name v_ini: 'Parâmetros'!$B$2
Name v_ger: 'Parâmetros'!$B$3
Name v_mc: 'Parâmetros'!$B$4

Sheet LEIA-ME
A1: IMQN — Qualidade Regulatória das 12 agências federais · workbook de trabalho (rev2022)
A2: Base: planilha "Matriz de Avaliação da Maturidade da Qualidade Normativa" (programa INFRA Competitividade, rev2022). Estrutura reescrita aqui de forma própria.
A4: COMO USAR
A5: 1. Aba "Avaliação": uma linha por agência × condição (12 × 73 = 876). Preencha só as células amarelas: Resposta (SIM / NÃO / ?), URL da evidência, data da consulta, status.
A6: 2. Use a aba "Roteiro" para abrir uma busca direcionada ao portal da agência, por critério. O portal raiz e a lei de criação estão em "Agências".
A7: 3. A aba "Cálculo" aplica a regra de nível e a aba "Ranking" soma tudo. Nada precisa ser digitado nelas.
A9: REGRA DE NÍVEL (decisão metodológica deste workbook — a planilha original não a define)
A10: • Níveis cumulativos: Inexistente (0) → Inicial (0,35) → Gerenciado (0,70) → Melhoria Contínua (1,00). Valores editáveis em "Parâmetros".
A11: • Para cada critério: o nível-base é o mais alto cujas condições estão TODAS atendidas (e todas as dos níveis abaixo). A fração do nível seguinte é a proporção das condições dele atendidas.
A12: • Exemplo: Inicial completo + 2 de 4 condições do Gerenciado → 0,35 + 0,35 × 0,5 = 0,525. Condição de nível acima de uma lacuna não conta (maturidade não pula degrau).
A13: • Nota da dimensão = Σ (peso do critério na dimensão × classificação) × peso da dimensão. IMQN = Σ das 6 dimensões (0–100). Pesos: AIR 25 · Estoque 20 · Participação Social 15 · Agenda 15 · ARR 15 · Processo 10.
A15: DUAS NOTAS, NUNCA UMA SÓ
... A24: ABAS: Parâmetros · Dimensões · Critérios · Condições · Agências · Roteiro · Avaliação · Cálculo · Ranking · Auditoria

Sheet Parâmetros
A1: Nível | B1: Valor | C1: Nome
A2: Inicial | B2: 0.35 | C2: v_ini
A3: Gerenciado | B3: 0.7 | C3: v_ger
A4: Melhoria Contínua | B4: 1 | C4: v_mc
A6: Inexistente = 0 (fixo). Peso dos critérios e dimensões nas abas Critérios/Dimensões.

Sheet Dimensões
A1: ID | B1: Dimensão | C1: Peso (pts) | D1: O que mede | E1: Base legal | F1: Base legal conferida?
A2: 1 | B2: Análise de Impacto Regulatório (AIR) | C2: 25 | D2: A agência avalia impacto e alternativas antes de criar norma? | E2: Lei 13.848/2019, art. 6º; Lei 13.874/2019, art. 5º; Decreto 10.411/2020 | F2: Não
A3: 2 | B3: Participação Social | C3: 15 | D3: Consultas e audiências, com devolutiva às contribuições? | E3: Lei 13.848/2019, arts. 9º a 11; Lei 13.874/2019; Decreto 10.411/2020 | F3: Não
A4: 3 | B4: Gestão de Estoque Regulatório | C4: 20 | D4: Acervo normativo levantado, indexado e consolidado? | E4: Decreto 10.139/2019, art. 19; Lei 13.874/2019 | F4: Não
A5: 4 | B5: Agenda Regulatória | C5: 15 | D5: Planejamento público do que será regulado — e cumprido? | E5: Lei 13.848/2019, art. 21 | F5: Não
A6: 5 | B6: Gestão do Processo Normativo | C6: 10 | D6: Fluxo de criação de normas padronizado e monitorado? | E6: Lei 13.848/2019; Decreto 10.411/2020 | F6: Não
A7: 6 | B7: Análise de Resultado Regulatório (ARR) | C7: 15 | D7: Normas em vigor são reavaliadas depois de aplicadas? | E7: Decreto 10.411/2020 (ARR) — artigo a conferir | F7: Não
B8: TOTAL | C8: =SUM(C2:C7)

Sheet Critérios
A1: Código | B1: Critério | C1: Dim. | D1: Peso na dimensão | E1: Condições Inicial | F1: Condições Gerenciado | G1: Condições Melh. Contínua | H1: Total | I1: Termos de busca | J1: Onde procurar
A2: AIR_CAP | B2: Capacitação em AIR | C2: 1 | D2: 0.3 | E2: =COUNTIFS(Condições!$C$2:$C$74,$A2,Condições!$E$2:$E$74,"Inicial") | F2: =COUNTIFS(Condições!$C$2:$C$74,$A2,Condições!$E$2:$E$74,"Gerenciado") | G2: =COUNTIFS(Condições!$C$2:$C$74,$A2,Condições!$E$2:$E$74,"Melhoria Contínua") | H2: =SUM(E2:G2) | I2: capacitação AIR; curso análise de impacto regulatório; plano de capacitação | J2: Dado interno: relatório de gestão, plano de desenvolvimento de pessoas, listas de certificados (agregadas, sem identificar servidores)
A3: AIR_MET | B3: Metodologia de AIR | C3: 1 | D3: 0.35 | E3: =COUNTIFS(Condições!$C$2:$C$74,$A3,Condições!$E$2:$E$74,"Inicial") | F3: =COUNTIFS(Condições!$C$2:$C$74,$A3,Condições!$E$2:$E$74,"Gerenciado") | G3: =COUNTIFS(Condições!$C$2:$C$74,$A3,Condições!$E$2:$E$74,"Melhoria Contínua") | H3: =SUM(E3:G3) | I3: manual de AIR; análise de impacto regulatório metodologia; portaria AIR | J3: Portal > Institucional / Acesso à informação > legislação interna; Boletim de Serviço
A4: AIR_PRO | B4: Processo de AIR | C4: 1 | D4: 0.35 | E4: =COUNTIFS(Condições!$C$2:$C$74,$A4,Condições!$E$2:$E$74,"Inicial") | F4: =COUNTIFS(Condições!$C$2:$C$74,$A4,Condições!$E$2:$E$74,"Gerenciado") | G4: =COUNTIFS(Condições!$C$2:$C$74,$A4,Condições!$E$2:$E$74,"Melhoria Contínua") | H4: =SUM(E4:G4) | I4: relatório de AIR; AIR dispensa; nota técnica AIR | J4: Portal > Regulação / Participação social > consultas públicas (anexos de AIR)
A5: PS | B5: Participação Social | C5: 2 | D5: 1 | E5: =COUNTIFS(Condições!$C$2:$C$74,$A5,Condições!$E$2:$E$74,"Inicial") | F5: =COUNTIFS(Condições!$C$2:$C$74,$A5,Condições!$E$2:$E$74,"Gerenciado") | G5: =COUNTIFS(Condições!$C$2:$C$74,$A5,Condições!$E$2:$E$74,"Melhoria Contínua") | H5: =SUM(E5:G5) | I5: consulta pública; audiência pública; tomada de subsídios; Participa + Brasil; relatório ouvidoria; consumidor.gov.br | J5: Portal > Participação social; plataforma Participa + Brasil; relatório anual da Ouvidoria
A6: EST | B6: Gestão de Estoque Regulatório | C6: 3 | D6: 1 | E6: =COUNTIFS(Condições!$C$2:$C$74,$A6,Condições!$E$2:$E$74,"Inicial") | F6: =COUNTIFS(Condições!$C$2:$C$74,$A6,Condições!$E$2:$E$74,"Gerenciado") | G6: =COUNTIFS(Condições!$C$2:$C$74,$A6,Condições!$E$2:$E$74,"Melhoria Contínua") | H6: =SUM(E6:G6) | I6: acervo normativo; consolidação normativa; estoque regulatório; fardo regulatório; revisão de normas | J6: Portal > Legislação / Normas; relatórios de revisão do estoque
A7: AGE | B7: Agenda Regulatória | C7: 4 | D7: 1 | E7: =COUNTIFS(Condições!$C$2:$C$74,$A7,Condições!$E$2:$E$74,"Inicial") | F7: =COUNTIFS(Condições!$C$2:$C$74,$A7,Condições!$E$2:$E$74,"Gerenciado") | G7: =COUNTIFS(Condições!$C$2:$C$74,$A7,Condições!$E$2:$E$74,"Melhoria Contínua") | H7: =SUM(E7:G7) | I7: agenda regulatória; relatório de acompanhamento da agenda; ciclo bienal | J7: Portal > Regulação > Agenda regulatória; relatório anual
A8: PRO | B8: Gestão do Processo Normativo | C8: 5 | D8: 1 | E8: =COUNTIFS(Condições!$C$2:$C$74,$A8,Condições!$E$2:$E$74,"Inicial") | F8: =COUNTIFS(Condições!$C$2:$C$74,$A8,Condições!$E$2:$E$74,"Gerenciado") | G8: =COUNTIFS(Condições!$C$2:$C$74,$A8,Condições!$E$2:$E$74,"Melhoria Contínua") | H8: =SUM(E8:G8) | I8: processo normativo; fluxo de elaboração de normas; indicadores processo normativo; manual de elaboração de atos normativos | J8: Portal > Institucional > processos; Boletim de Serviço; relatório de gestão
A9: ARR_CAP | B9: Capacitação em ARR | C9: 6 | D9: 0.3 | E9: =COUNTIFS(Condições!$C$2:$C$74,$A9,Condições!$E$2:$E$74,"Inicial") | F9: =COUNTIFS(Condições!$C$2:$C$74,$A9,Condições!$E$2:$E$74,"Gerenciado") | G9: =COUNTIFS(Condições!$C$2:$C$74,$A9,Condições!$E$2:$E$74,"Melhoria Contínua") | H9: =SUM(E9:G9) | I9: capacitação ARR; análise de resultado regulatório curso | J9: Dado interno: relatório de gestão, plano de desenvolvimento de pessoas
A10: ARR_MET | B10: Metodologia de ARR | C10: 6 | D10: 0.35 | E10: =COUNTIFS(Condições!$C$2:$C$74,$A10,Condições!$E$2:$E$74,"Inicial") | F10: =COUNTIFS(Condições!$C$2:$C$74,$A10,Condições!$E$2:$E$74,"Gerenciado") | G10: =COUNTIFS(Condições!$C$2:$C$74,$A10,Condições!$E$2:$E$74,"Melhoria Contínua") | H10: =SUM(E10:G10) | I10: agenda de ARR; manual ARR; análise de resultado regulatório metodologia | J10: Portal > Regulação > Agenda de ARR; Boletim de Serviço
A11: ARR_PRO | B11: Processo de ARR | C11: 6 | D11: 0.35 | E11: =COUNTIFS(Condições!$C$2:$C$74,$A11,Condições!$E$2:$E$74,"Inicial") | F11: =COUNTIFS(Condições!$C$2:$C$74,$A11,Condições!$E$2:$E$74,"Gerenciado") | G11: =COUNTIFS(Condições!$C$2:$C$74,$A11,Condições!$E$2:$E$74,"Melhoria Contínua") | H11: =SUM(E11:G11) | I11: relatório de ARR; análise de resultado regulatório publicada | J11: Portal > Regulação > ARR; consultas públicas de ARR
B12: Conferência: Σ pesos dentro de cada dimensão deve ser 1

Sheet Condições
A1: ID | B1: Dim. | C1: Critério | D1: Nível-chave | E1: Nível | F1: Ordem | G1: Condição (texto da matriz, corrigido) | H1: Pergunta sim/não | I1: Verificabilidade (proposta) | J1: Tipo de evidência | K1: Por quê | L1: Base legal | M1: Texto original
A2: AIR_CAP.MC.I | B2: 1 | C2: AIR_CAP | D2: melhoria_continua | E2: Melhoria Contínua | F2: I | G2: Plano de capacitação formalizado e em execução, incluindo permanente reciclagem em técnicas de AIR; | H2: Há evidência de que plano de capacitação formalizado e em execução, incluindo permanente reciclagem em técnicas de AIR? | I2: interna | J2: Dado interno | K2: Capacitação é dado de RH do órgão; não há documento público que a comprove por si. | L2: Lei 13.848/2019, art. 6º; Lei 13.874/2019, art. 5º; Decreto 10.411/2020 | M2: I – Plano de capacitação formalizado e em execução, incluindo permanente reciclagem em técnicas de AIR;
A3: AIR_CAP.GER.I | B3: 1 | C3: AIR_CAP | D3: gerenciado | E3: Gerenciado | F3: I | G3: Capacitações em AIR estão institucionalizadas, sem um plano formalizado; | H3: Há evidência de que capacitações em AIR estão institucionalizadas, sem um plano formalizado? | I3: interna | J3: Dado interno | K3: Capacitação é dado de RH do órgão; não há documento público que a comprove por si. | L3: Lei 13.848/2019, art. 6º; Lei 13.874/2019, art. 5º; Decreto 10.411/2020 | M3: I – Capacitações em AIR estão institucionalizadas, sem um plano formalizado;
A4: AIR_CAP.INI.I | B4: 1 | C4: AIR_CAP | D4: inicial | E4: Inicial | F4: I | G4: Capacitações em AIR não estão institucionalizadas; | H4: Há evidência de que capacitações em AIR não estão institucionalizadas? | I4: interna | J4: Dado interno | K4: Capacitação é dado de RH do órgão; não há documento público que a comprove por si. | L4: Lei 13.848/2019, art. 6º; Lei 13.874/2019, art. 5º; Decreto 10.411/2020 | M4: I - Capacitações em AIR não estão institucionalizadas;
A5: AIR_CAP.MC.II | B5: 1 | C5: AIR_CAP | D5: melhoria_continua | E5: Melhoria Contínua | F5: II | G5: no mínimo 75% dos servidores envolvidos em elaboração de regulação capacitados em nível intermediário, ou seja, capazes de desenvolver as etapas de mapeamento do problema (incluindo atores, objetivos e base legal), levantamento de alternativas, análises qualitativas dos impactos das alternativas e elaboração do plano de implementação da alternativa sugerida; | H5: Há evidência de que no mínimo 75% dos servidores envolvidos em elaboração de regulação capacitados em nível intermediário, ou seja, capazes de desenvolver as etapas de mapeamento do problema (incluindo atores, objetivos e base legal), levantamento de alternativas, análises qualitativas dos impactos das alternativas e elaboração do plano de implementação da alternativa sugerida? | I5: interna | J5: Indicador numérico | K5: Capacitação é dado de RH do órgão; não há documento público que a comprove por si. | L5: Lei 13.848/2019, art. 6º; Lei 13.874/2019, art. 5º; Decreto 10.411/2020 | M5: II – no mínimo 75% dos servidores envolvidos em elaboração de regulação capacitados em nível intermediário, ou seja, capazes de desenvolver as etapas de mapeamento do problema (incluindo atores, objetivos e base legal), levantamento de alternativas, análises qualitativas dos impactos das alternativas e elaboração do plano de implementação da alternativa sugerida;
A6: AIR_CAP.GER.II | B6: 1 | C6: AIR_CAP | D6: gerenciado | E6: Gerenciado | F6: II | G6: no mínimo 75% dos servidores envolvidos em elaboração de regulação capacitados em nível básico, ou seja, capazes de reconhecer o objetivo de uma AIR, bem como nomear as etapas de uma AIR e possibilidades de dispensa e não aplicabilidade, nos termos no Decreto nº 10.411, de 2020; | H6: Há evidência de que no mínimo 75% dos servidores envolvidos em elaboração de regulação capacitados em nível básico, ou seja, capazes de reconhecer o objetivo de uma AIR, bem como nomear as etapas de uma AIR e possibilidades de dispensa e não aplicabilidade, nos termos no Decreto nº 10.411, de 2020? | I6: interna | J6: Indicador numérico | K6: Capacitação é dado de RH do órgão; não há documento público que a comprove por si. | L6: Lei 13.848/2019, art. 6º; Lei 13.874/2019, art. 5º; Decreto 10.411/2020 | M6: II – no mínimo 75% dos servidores envolvidos em elaboração de regulação capacitados em nível básico, ou seja, capazes de reconhecer o objetivo de uma AIR, bem como nomear as etapas de uma AIR e possibilidades de dispensa e não aplicabilidade, nos termos no Decreto nº 10.411, de 2020;
A7: AIR_CAP.INI.II | B7: 1 | C7: AIR_CAP | D7: inicial | E7: Inicial | F7: II | G7: de 50% a 74% dos servidores envolvidos em elaboração de regulação capacitados em nível básico, ou seja, capazes de reconhecer o objetivo de uma AIR, bem como nomear as etapas de uma AIR e possibilidades de dispensa e não aplicabilidade, nos termos no Decreto nº 10.411, de 30 de junho de 2020; | H7: Há evidência de que de 50% a 74% dos servidores envolvidos em elaboração de regulação capacitados em nível básico, ou seja, capazes de reconhecer o objetivo de uma AIR, bem como nomear as etapas de uma AIR e possibilidades de dispensa e não aplicabilidade, nos termos no Decreto nº 10.411, de 30 de junho de 2020? | I7: interna | J7: Indicador numérico | K7: Capacitação é dado de RH do órgão; não há documento público que a comprove por si. | L7: Lei 13.848/2019, art. 6º; Lei 13.874/2019, art. 5º; Decreto 10.411/2020 | M7: II - de 50% a 74% dos servidores envolvidos em elaboração de regulação capacitados em nível básico, ou seja, capazes de reconhecer o objetivo de uma AIR, bem como nomear as etapas de uma AIR e possibilidades de dispensa e não aplicabilidade, nos termos no Decreto nº 10.411, de 30 de junho de2020;
A8: AIR_CAP.MC.III | B8: 1 | C8: AIR_CAP | D8: melhoria_continua | E8: Melhoria Contínua | F8: III | G8: no mínimo 50% dos servidores envolvidos em elaboração de regulação capacitados em nível avançado, ou seja, capazes de desenvolver as etapas de mapeamento do problema (incluindo atores, objetivos e base legal), levantamento de alternativas, análises qualitativas e quantitativas dos impactos das alternativas e elaboração do plano de implementação da alternativa sugerida (incluindo avaliação de riscos). | H8: Há evidência de que no mínimo 50% dos servidores envolvidos em elaboração de regulação capacitados em nível avançado, ou seja, capazes de desenvolver as etapas de mapeamento do problema (incluindo atores, objetivos e base legal), levantamento de alternativas, análises qualitativas e quantitativas dos impactos das alternativas e elaboração do plano de implementação da alternativa sugerida (incluindo avaliação de riscos)? | I8: interna | J8: Indicador numérico | K8: Capacitação é dado de RH do órgão; não há documento público que a comprove por si. | L8: Lei 13.848/2019, art. 6º; Lei 13.874/2019, art. 5º; Decreto 10.411/2020 | M8: III – no mínimo 50% dos servidores envolvidos em elaboração de regulação capacitados em nível avançado, ou seja, capazes de desenvolver as etapas de mapeamento do problema (incluindo atores, objetivos e base legal), levantamento de alternativas, análises qualitativas e quantitativas dos impactos das alternativas e elaboração do plano de implementação da alternativa sugerida (incluindo avaliação de riscos).
A9: AIR_CAP.GER.III | B9: 1 | C9: AIR_CAP | D9: gerenciado | E9: Gerenciado | F9: III | G9: de 50% a 74% dos servidores envolvidos em elaboração de regulação capacitados em nível intermediário, ou seja, capazes de desenvolver as etapas de mapeamento do problema (incluindo atores, objetivos e base legal), levantamento de alternativas, análises qualitativas dos impactos das alternativas e elaboração do plano de implementação da alternativa sugerida; | H9: Há evidência de que de 50% a 74% dos servidores envolvidos em elaboração de regulação capacitados em nível intermediário, ou seja, capazes de desenvolver as etapas de mapeamento do problema (incluindo atores, objetivos e base legal), levantamento de alternativas, análises qualitativas dos impactos das alternativas e elaboração do plano de implementação da alternativa sugerida? | I9: interna | J9: Indicador numérico | K9: Capacitação é dado de RH do órgão; não há documento público que a comprove por si. | L9: Lei 13.848/2019, art. 6º; Lei 13.874/2019, art. 5º; Decreto 10.411/2020 | M9: III – de 50% a 74% dos servidores envolvidos em elaboração de regulação capacitados em nível intermediário, ou seja, capazes de desenvolver as etapas de mapeamento do problema (incluindo atores, objetivos e base legal), levantamento de alternativas, análises qualitativas dos impactos das alternativas e elaboração do plano de implementação da alternativa sugerida;
A10: AIR_CAP.INI.III | B10: 1 | C10: AIR_CAP | D10: inicial | E10: Inicial | F10: III | G10: de 25% a 49% dos servidores envolvidos em elaboração de regulação capacitados em nível intermediário, ou seja, capazes de desenvolver as etapas de mapeamento do problema (incluindo atores, objetivos e base legal), levantamento de alternativas, análises qualitativas dos impactos das alternativas e elaboração do plano de implementação da alternativa sugerida. | H10: Há evidência de que de 25% a 49% dos servidores envolvidos em elaboração de regulação capacitados em nível intermediário, ou seja, capazes de desenvolver as etapas de mapeamento do problema (incluindo atores, objetivos e base legal), levantamento de alternativas, análises qualitativas dos impactos das alternativas e elaboração do plano de implementação da alternativa sugerida? | I10: interna | J10: Indicador numérico | K10: Capacitação é dado de RH do órgão; não há documento público que a comprove por si. | L10: Lei 13.848/2019, art. 6º; Lei 13.874/2019, art. 5º; Decreto 10.411/2020 | M10: III – de 25% a 49% dos servidores envolvidos em elaboração de regulação capacitados em nível intermediário, ou seja, capazes de desenvolver as etapas de mapeamento do problema (incluindo atores, objetivos e base legal), levantamento de alternativas, análises qualitativas dos impactos das alternativas e elaboração do plano de implementação da alternativa sugerida.
A11: AIR_CAP.GER.IV | B11: 1 | C11: AIR_CAP | D11: gerenciado | E11: Gerenciado | F11: IV | G11: de 25% a 49% dos servidores envolvidos em elaboração de regulação capacitados em nível avançado, ou seja, capazes de desenvolver as etapas de mapeamento do problema (incluindo atores, objetivos e base legal), levantamento de alternativas, análises qualitativas e quantitativas dos impactos das alternativas e elaboração do plano de implementação da alternativa sugerida (incluindo avaliação de riscos). | H11: Há evidência de que de 25% a 49% dos servidores envolvidos em elaboração de regulação capacitados em nível avançado, ou seja, capazes de desenvolver as etapas de mapeamento do problema (incluindo atores, objetivos e base legal), levantamento de alternativas, análises qualitativas e quantitativas dos impactos das alternativas e elaboração do plano de implementação da alternativa sugerida (incluindo avaliação de riscos)? | I11: interna | J11: Indicador numérico | K11: Capacitação é dado de RH do órgão; não há documento público que a comprove por si. | L11: Lei 13.848/2019, art. 6º; Lei 13.874/2019, art. 5º; Decreto 10.411/2020 | M11: IV – de 25% da 49% dos servidores envolvidos em elaboração de regulação capacitados em nível avançado, ou seja, capazes de desenvolver as etapas de mapeamento do problema (incluindo atores, objetivos e base legal), levantamento de alternativas, análises qualitativas e quantitativas dos impactos das alternativas e elaboração do plano de implementação da alternativa sugerida (incluindo avaliação de riscos).
A12: AIR_MET.MC.I | B12: 1 | C12: AIR_MET | D12: melhoria_continua | E12: Melhoria Contínua | F12: I | G12: Critérios objetivos estabelecidos para classificação quanto ao nível de impacto e complexidade da AIR; | H12: Há evidência de que critérios objetivos estabelecidos para classificação quanto ao nível de impacto e complexidade da AIR? | I12: interna | J12: Dado interno | K12: Prática de gestão sem documento público típico (ex.: monitoramento, integração ao planejamento). | L12: Lei 13.848/2019, art. 6º; Lei 13.874/2019, art. 5º; Decreto 10.411/2020 | M12: I – Critérios objetivos estabelecidos para classificação quanto ao nível de impacto e complexidade da AIR;
A13: AIR_MET.GER.I | B13: 1 | C13: AIR_MET | D13: gerenciado | E13: Gerenciado | F13: I | G13: Existência de manual ou ato normativo interno instituindo a aplicabilidade institucional da AIR; | H13: Há evidência de que existência de manual ou ato normativo interno instituindo a aplicabilidade institucional da AIR? | I13: pública | J13: Documento público (ato/manual publicável) | K13: Depende de o ato estar publicado; se não estiver, só dado interno. | L13: Lei 13.848/2019, art. 6º; Lei 13.874/2019, art. 5º; Decreto 10.411/2020 | M13: I – Existência de manual ou ato normativo interno instituindo a aplicabilidade institucional da AIR;
A14: AIR_MET.INI.I | B14: 1 | C14: AIR_MET | D14: inicial | E14: Inicial | F14: I | G14: houve a publicação de normativo interno dispondo sobre a aplicação da AIR na instituição, conforme Decreto nº 10.411, de 2020. | H14: Há evidência de que houve a publicação de normativo interno dispondo sobre a aplicação da AIR na instituição, conforme Decreto nº 10.411, de 2020? | I14: pública | J14: Documento público | L14: Lei 13.848/2019, art. 6º; Lei 13.874/2019, art. 5º; Decreto 10.411/2020 | M14: I - houve a publicação de normativo interno dispondo sobre a aplicação da AIR na instituição, conforme Decreto nº 10.411, de 2020.
A15: AIR_MET.MC.II | B15: 1 | C15: AIR_MET | D15: melhoria_continua | E15: Melhoria Contínua | F15: II | G15: Metodologia contempla participação social prévia e posterior à elaboração da AIR, conforme complexidade do ato. | H15: Há evidência de que metodologia contempla participação social prévia e posterior à elaboração da AIR, conforme complexidade do ato? | I15: pública | J15: Documento público (ato/manual publicável) | K15: Depende de o ato estar publicado; se não estiver, só dado interno. | L15: Lei 13.848/2019, art. 6º; Lei 13.874/2019, art. 5º; Decreto 10.411/2020 | M15: II – Metodologia contempla participação social prévia e posterior à elaboração da AIR, conforme complexidade do ato.
A16: AIR_MET.GER.II | B16: 1 | C16: AIR_MET | D16: gerenciado | E16: Gerenciado | F16: II | G16: Existência de manual ou ato normativo dispondo sobre a participação social posterior relativa à AIR. | H16: Há evidência de que existência de manual ou ato normativo dispondo sobre a participação social posterior relativa à AIR? | I16: pública | J16: Documento público (ato/manual publicável) | K16: Depende de o ato estar publicado; se não estiver, só dado interno. | L16: Lei 13.848/2019, art. 6º; Lei 13.874/2019, art. 5º; Decreto 10.411/2020 | M16: II – Existência de manual ou ato normativo dispondo sobre a participação social posterior relativa à AIR.
A17: AIR_PRO.MC.I | B17: 1 | C17: AIR_PRO | D17: melhoria_continua | E17: Melhoria Contínua | F17: I | G17: Há processo contínuo de avaliação e melhoria do processo de elaboração de AIR; | H17: Há evidência de que há processo contínuo de avaliação e melhoria do processo de elaboração de AIR? | I17: interna | J17: Dado interno | K17: Prática de gestão sem documento público típico (ex.: monitoramento, integração ao planejamento). | L17: Lei 13.848/2019, art. 6º; Lei 13.874/2019, art. 5º; Decreto 10.411/2020 | M17: I – Há processo contínuo de avaliação e melhoria do processo de elaboração de AIR;
A18: AIR_PRO.GER.I | B18: 1 | C18: AIR_PRO | D18: gerenciado | E18: Gerenciado | F18: I | G18: Todas as AIRs são sempre realizadas conforme manual ou ato normativo interno e publicadas e acessíveis ao público na internet; | H18: Há evidência de que todas as AIRs são sempre realizadas conforme manual ou ato normativo interno e publicadas e acessíveis ao público na internet? | I18: pública | J18: Documento público | L18: Lei 13.848/2019, art. 6º; Lei 13.874/2019, art. 5º; Decreto 10.411/2020 | M18: I – Todas as AIRs são sempre realizadas conforme manual ou ato normativo interno e publicadas e acessíveis ao público na internet;
A19: AIR_PRO.INI.I | B19: 1 | C19: AIR_PRO | D19: inicial | E19: Inicial | F19: I | G19: AIR é sempre realizada e a dispensa justificada, conforme critérios objetivos estabelecidos, conforme Decreto nº 10.411, de 2020; | H19: Há evidência de que aIR é sempre realizada e a dispensa justificada, conforme critérios objetivos estabelecidos, conforme Decreto nº 10.411, de 2020? | I19: interna | J19: Dado interno | K19: Prática de gestão sem documento público típico (ex.: monitoramento, integração ao planejamento). | L19: Lei 13.848/2019, art. 6º; Lei 13.874/2019, art. 5º; Decreto 10.411/2020 | M19: I – AIR é sempre realizada e a dispensa justificada, conforme critérios objetivos estabelecidos, conforme Decreto nº 10.411, de 2020;
A20: AIR_PRO.MC.II | B20: 1 | C20: AIR_PRO | D20: melhoria_continua | E20: Melhoria Contínua | F20: II | G20: Existência de instrumento de avaliação de qualidade das AIRs realizadas; | H20: Há evidência de que existência de instrumento de avaliação de qualidade das AIRs realizadas? | I20: interna | J20: Dado interno | K20: Prática de gestão sem documento público típico (ex.: monitoramento, integração ao planejamento). | L20: Lei 13.848/2019, art. 6º; Lei 13.874/2019, art. 5º; Decreto 10.411/2020 | M20: II – Existência de instrumento de avaliação de qualidade das AIRs realizadas;
A21: AIR_PRO.GER.II | B21: 1 | C21: AIR_PRO | D21: gerenciado | E21: Gerenciado | F21: II | G21: O processo de elaboração de AIR está mapeado na instituição; | H21: Há evidência de que o processo de elaboração de AIR está mapeado na instituição? | I21: interna | J21: Dado interno | K21: Prática de gestão sem documento público típico (ex.: monitoramento, integração ao planejamento). | L21: Lei 13.848/2019, art. 6º; Lei 13.874/2019, art. 5º; Decreto 10.411/2020 | M21: II – O processo de elaboração de AIR está mapeado na instituição;
A22: AIR_PRO.INI.II | B22: 1 | C22: AIR_PRO | D22: inicial | E22: Inicial | F22: II | G22: Todas as AIRs são publicadas e acessíveis ao público na internet; | H22: Há evidência de que todas as AIRs são publicadas e acessíveis ao público na internet? | I22: pública | J22: Documento público | L22: Lei 13.848/2019, art. 6º; Lei 13.874/2019, art. 5º; Decreto 10.411/2020 | M22: II – Todas as AIRs são publicadas e acessíveis ao público na internet;
A23: AIR_PRO.MC.III | B23: 1 | C23: AIR_PRO | D23: melhoria_continua | E23: Melhoria Contínua | F23: III | G23: As AIRs de alto impacto/alta complexidade são submetidas à participação social prévia e posterior. | H23: Há evidência de que as AIRs de alto impacto/alta complexidade são submetidas à participação social prévia e posterior? | I23: interna | J23: Dado interno | K23: Prática de gestão sem documento público típico (ex.: monitoramento, integração ao planejamento). | L23: Lei 13.848/2019, art. 6º; Lei 13.874/2019, art. 5º; Decreto 10.411/2020 | M23: III – As AIRs de alto impacto/alta complexidade são submetidas à participação social prévia e posterior.
A24: AIR_PRO.GER.III | B24: 1 | C24: AIR_PRO | D24: gerenciado | E24: Gerenciado | F24: III | G24: As AIRs são objeto de participação social posterior, conforme decisão técnica. | H24: Há evidência de que as AIRs são objeto de participação social posterior, conforme decisão técnica? | I24: interna | J24: Dado interno | K24: Prática de gestão sem documento público típico (ex.: monitoramento, integração ao planejamento). | L24: Lei 13.848/2019, art. 6º; Lei 13.874/2019, art. 5º; Decreto 10.411/2020 | M24: III – As AIRs são objeto de participação social posterior, conforme decisão técnica.
A25: AIR_PRO.INI.III | B25: 1 | C25: AIR_PRO | D25: inicial | E25: Inicial | F25: III | G25: Participação Social é realizada, conforme Decreto nº 10.411, de 2020. | H25: Há evidência de que participação Social é realizada, conforme Decreto nº 10.411, de 2020? | I25: interna | J25: Dado interno | K25: Prática de gestão sem documento público típico (ex.: monitoramento, integração ao planejamento). | L25: Lei 13.848/2019, art. 6º; Lei 13.874/2019, art. 5º; Decreto 10.411/2020 | M25: III – Participação Social é realizada, conforme Decreto nº 10.411, de 2020.
A26: PS.MC.I | B26: 2 | C26: PS | D26: melhoria_continua | E26: Melhoria Contínua | F26: I | G26: A instituição realiza eventos de participação social para a construção do conhecimento sobre dada matéria e para o desenvolvimento de propostas; | H26: Há evidência de que a instituição realiza eventos de participação social para a construção do conhecimento sobre dada matéria e para o desenvolvimento de propostas? | I26: interna | J26: Dado interno | K26: Prática de gestão sem documento público típico (ex.: monitoramento, integração ao planejamento). | L26: Lei 13.848/2019, arts. 9º a 11; Lei 13.874/2019; Decreto 10.411/2020 | M26: I – A instituição realiza eventos de participação social para a construção do conhecimento sobre dada matéria e para o desenvolvimento de propostas;
A27: PS.GER.I | B27: 2 | C27: PS | D27: gerenciado | E27: Gerenciado | F27: I | G27: Existência de manual ou ato normativo interno instituindo metodologia e procedimento de participação social; | H27: Há evidência de que existência de manual ou ato normativo interno instituindo metodologia e procedimento de participação social? | I27: pública | J27: Documento público (ato/manual publicável) | K27: Depende de o ato estar publicado; se não estiver, só dado interno. | L27: Lei 13.848/2019, arts. 9º a 11; Lei 13.874/2019; Decreto 10.411/2020 | M27: I – Existência de manual ou ato normativo interno instituindo metodologia e procedimento de participação social;
A28: PS.INI.I | B28: 2 | C28: PS | D28: inicial | E28: Inicial | F28: I | G28: existe dispositivo interno orientando a participação social conforme disposto na legislação específica vigente, tais como as Leis nº 13.848, de 25 de junho de 2019 e nº 13.874, de 20 de setembro de 2019 e o Decreto nº 10.411, de 2020. | H28: Há evidência de que existe dispositivo interno orientando a participação social conforme disposto na legislação específica vigente, tais como as Leis nº 13.848, de 25 de junho de 2019 e nº 13.874, de 20 de setembro de 2019 e o Decreto nº 10.411, de 2020? | I28: interna | J28: Dado interno | K28: Prática de gestão sem documento público típico (ex.: monitoramento, integração ao planejamento). | L28: Lei 13.848/2019, arts. 9º a 11; Lei 13.874/2019; Decreto 10.411/2020 | M28: I - existe dispositivo interno orientando a participação social conforme disposto na legislação específica vigente, tais como as Leis nº 13.848, de 25 de junho de 2019 e nº 13.874, de 20 de setembro de 2019 e o Decreto nº 10.411, de 2020.
A29: PS.MC.II | B29: 2 | C29: PS | D29: melhoria_continua | E29: Melhoria Contínua | F29: II | G29: Relatórios da Ouvidoria, relatórios do portal consumidor.gov, pesquisas de satisfação e dados de atendimento são utilizados para subsidiar as decisões regulatórias; | H29: Há evidência de que relatórios da Ouvidoria, relatórios do portal consumidor.gov, pesquisas de satisfação e dados de atendimento são utilizados para subsidiar as decisões regulatórias? | I29: pública | J29: Documento público | L29: Lei 13.848/2019, arts. 9º a 11; Lei 13.874/2019; Decreto 10.411/2020 | M29: II – Relatórios da Ouvidoria, relatórios do portal consumidor.gov, pesquisas de satisfação e dados de atendimento são utilizados para subsidiar as decisões regulatórias;
A30: PS.GER.II | B30: 2 | C30: PS | D30: gerenciado | E30: Gerenciado | F30: II | G30: Os relatórios da Ouvidoria e os relatórios do portal consumidor.gov são utilizados para subsidiar as decisões regulatórias; | H30: Há evidência de que os relatórios da Ouvidoria e os relatórios do portal consumidor.gov são utilizados para subsidiar as decisões regulatórias? | I30: pública | J30: Documento público | L30: Lei 13.848/2019, arts. 9º a 11; Lei 13.874/2019; Decreto 10.411/2020 | M30: II – Os relatórios da Ouvidoria e os relatórios do portal consumidor.gov são utilizados para subsidiar as decisões regulatórias;
A31: PS.MC.III | B31: 2 | C31: PS | D31: melhoria_continua | E31: Melhoria Contínua | F31: III | G31: Todos os instrumentos, processos e relatórios contendo as contribuições analisadas são divulgados no portal do órgão e/ou plataforma Participa Mais Brasil; | H31: Há evidência de que todos os instrumentos, processos e relatórios contendo as contribuições analisadas são divulgados no portal do órgão e/ou plataforma Participa Mais Brasil? | I31: pública | J31: Documento público | L31: Lei 13.848/2019, arts. 9º a 11; Lei 13.874/2019; Decreto 10.411/2020 | M31: III – Todos os instrumentos, processos e relatórios contendo as contribuições analisadas são divulgados no portal do órgão e/ou plataforma Participa Mais Brasil;
A32: PS.GER.III | B32: 2 | C32: PS | D32: gerenciado | E32: Gerenciado | F32: III | G32: Todas as informações relativas aos processos em andamento são divulgadas no portal do órgão e/ou plataforma Participa Mais Brasil; | H32: Há evidência de que todas as informações relativas aos processos em andamento são divulgadas no portal do órgão e/ou plataforma Participa Mais Brasil? | I32: pública | J32: Documento público | L32: Lei 13.848/2019, arts. 9º a 11; Lei 13.874/2019; Decreto 10.411/2020 | M32: III – Todas as informações relativas aos processos em andamento são divulgadas no portal do órgão e/ou plataforma Participa Mais Brasil;
A33: PS.MC.IV | B33: 2 | C33: PS | D33: melhoria_continua | E33: Melhoria Contínua | F33: IV | G33: A efetividade do evento de participação social é mensurada, conforme metodologia instituída. | H33: Há evidência de que a efetividade do evento de participação social é mensurada, conforme metodologia instituída? | I33: pública | J33: Documento público (ato/manual publicável) | K33: Depende de o ato estar publicado; se não estiver, só dado interno. | L33: Lei 13.848/2019, arts. 9º a 11; Lei 13.874/2019; Decreto 10.411/2020 | M33: IV – A efetividade do evento de participação social é mensurada, conforme metodologia instituída.
A34: PS.GER.IV | B34: 2 | C34: PS | D34: gerenciado | E34: Gerenciado | F34: IV | G34: A efetividade do evento de participação social é avaliada de forma intuitiva. | H34: Há evidência de que a efetividade do evento de participação social é avaliada de forma intuitiva? | I34: interna | J34: Dado interno | K34: Prática de gestão sem documento público típico (ex.: monitoramento, integração ao planejamento). | L34: Lei 13.848/2019, arts. 9º a 11; Lei 13.874/2019; Decreto 10.411/2020 | M34: IV – A efetividade do evento de participação social é avaliada de forma intuitiva.
A35: EST.MC.I | B35: 3 | C35: EST | D35: melhoria_continua | E35: Melhoria Contínua | F35: I | G35: As alterações do estoque regulatório da instituição são priorizadas por meio de uma agenda regulatória; | H35: Há evidência de que as alterações do estoque regulatório da instituição são priorizadas por meio de uma agenda regulatória? | I35: pública | J35: Documento público (ato/manual publicável) | K35: Depende de o ato estar publicado; se não estiver, só dado interno. | L35: Decreto 10.139/2019, art. 19; Lei 13.874/2019 | M35: I – As alterações do estoque regulatório da instituição são priorizadas por meio de uma agenda regulatória;
A36: EST.GER.I | B36: 3 | C36: EST | D36: gerenciado | E36: Gerenciado | F36: I | G36: Normas publicadas e disponíveis de maneira sistematizada para consulta pública no portal gov.br; | H36: Há evidência de que normas publicadas e disponíveis de maneira sistematizada para consulta pública no portal gov.br? | I36: pública | J36: Documento público | L36: Decreto 10.139/2019, art. 19; Lei 13.874/2019 | M36: I – Normas publicadas e disponíveis de maneira sistematizada para consulta pública no portal gov.br;
A37: EST.INI.I | B37: 3 | C37: EST | D37: inicial | E37: Inicial | F37: I | G37: Normas publicadas e disponíveis de maneira sistematizada para consulta pública na internet; | H37: Há evidência de que normas publicadas e disponíveis de maneira sistematizada para consulta pública na internet? | I37: pública | J37: Documento público | L37: Decreto 10.139/2019, art. 19; Lei 13.874/2019 | M37: I – Normas publicadas e disponíveis de maneira sistematizada para consulta pública na internet;
A38: EST.MC.II | B38: 3 | C38: EST | D38: melhoria_continua | E38: Melhoria Contínua | F38: II | G38: Todas as novas normas passam pela análise de consolidação e compatibilização de normas vigentes. | H38: Há evidência de que todas as novas normas passam pela análise de consolidação e compatibilização de normas vigentes? | I38: pública | J38: Documento público (ato/manual publicável) | K38: Depende de o ato estar publicado; se não estiver, só dado interno. | L38: Decreto 10.139/2019, art. 19; Lei 13.874/2019 | M38: II – Todas as novas normas passam pela análise de consolidação e compatibilização de normas vigentes.
A39: EST.GER.II | B39: 3 | C39: EST | D39: gerenciado | E39: Gerenciado | F39: II | G39: Foi realizado levantamento quantitativo de todas as normas do órgão, bem como análise qualitativa, indexação e classificação por tema; | H39: Há evidência de que foi realizado levantamento quantitativo de todas as normas do órgão, bem como análise qualitativa, indexação e classificação por tema? | I39: pública | J39: Documento público (ato/manual publicável) | K39: Depende de o ato estar publicado; se não estiver, só dado interno. | L39: Decreto 10.139/2019, art. 19; Lei 13.874/2019 | M39: II – Foi realizado levantamento quantitativo de todas as normas do órgão, bem como análise qualitativa, indexação e classificação por tema;
A40: EST.INI.II | B40: 3 | C40: EST | D40: inicial | E40: Inicial | F40: II | G40: Foi realizado levantamento quantitativo de todas as normas do órgão. | H40: Há evidência de que foi realizado levantamento quantitativo de todas as normas do órgão? | I40: pública | J40: Documento público (ato/manual publicável) | K40: Depende de o ato estar publicado; se não estiver, só dado interno. | L40: Decreto 10.139/2019, art. 19; Lei 13.874/2019 | M40: II – Foi realizado levantamento quantitativo de todas as normas do órgão.
...

Sheet Agências
A1: Sigla | B1: Agência | C1: Setor | D1: Lei de criação | E1: Ministério supervisor | F1: Portal (raiz) | G1: Acesso do portal medido em 2026-10-09 | H1: Observação
A2: ANATEL | B2: Agência Nacional de Telecomunicações | C2: Telecomunicações | D2: Lei 9.472/1997 | E2: a conferir | F2: https://www.gov.br/anatel/pt-br | G2: HTTP 200
A3: ANVISA | B3: Agência Nacional de Vigilância Sanitária | C3: Vigilância sanitária | D3: Lei 9.782/1999 | E3: a conferir | F3: https://www.gov.br/anvisa/pt-br | G3: HTTP 200
A4: ANEEL | B4: Agência Nacional de Energia Elétrica | C4: Energia elétrica | D4: Lei 9.427/1996 | E4: a conferir | F4: https://www.gov.br/aneel/pt-br | G4: bloqueado (403) neste ambiente — conferir no navegador
A5: ANTT | B5: Agência Nacional de Transportes Terrestres | C5: Transporte terrestre | D5: Lei 10.233/2001 | E5: a conferir | F5: https://www.gov.br/antt/pt-br | G5: bloqueado (403) neste ambiente — conferir no navegador
A6: ANAC | B6: Agência Nacional de Aviação Civil | C6: Aviação civil | D6: Lei 11.182/2005 | E6: a conferir | F6: https://www.gov.br/anac/pt-br | G6: sem resposta — conferir no navegador
A7: ANTAQ | B7: Agência Nacional de Transportes Aquaviários | C7: Transporte aquaviário | D7: Lei 10.233/2001 | E7: a conferir | F7: https://www.gov.br/antaq/pt-br | G7: bloqueado (403) neste ambiente — conferir no navegador
A8: ANP | B8: Agência Nacional do Petróleo, Gás Natural e Biocombustíveis | C8: Petróleo, gás e biocombustíveis | D8: Lei 9.478/1997 | E8: a conferir | F8: https://www.gov.br/anp/pt-br | G8: bloqueado (403) neste ambiente — conferir no navegador
A9: ANA | B9: Agência Nacional de Águas e Saneamento Básico | C9: Recursos hídricos e saneamento | D9: Lei 9.984/2000 | E9: a conferir | F9: https://www.gov.br/ana/pt-br | G9: bloqueado (403) neste ambiente — conferir no navegador | H9: Regulação de saneamento (Lei 14.026/2020) inclui normas de referência — verificar agenda própria.
A10: ANS | B10: Agência Nacional de Saúde Suplementar | C10: Saúde suplementar | D10: Lei 9.961/2000 | E10: a conferir | F10: https://www.gov.br/ans/pt-br | G10: bloqueado (403) neste ambiente — conferir no navegador
A11: ANM | B11: Agência Nacional de Mineração | C11: Mineração | D11: Lei 13.575/2017 | E11: a conferir | F11: https://www.gov.br/anm/pt-br | G11: bloqueado (403) neste ambiente — conferir no navegador
A12: ANCINE | B12: Agência Nacional do Cinema | C12: Audiovisual | D12: MP 2.228-1/2001 | E12: a conferir | F12: https://www.gov.br/ancine/pt-br | G12: HTTP 200 | H12: Criada por MP 2.228-1/2001; verificar agenda regulatória bienal publicada.
A13: ANPD | B13: Autoridade Nacional de Proteção de Dados | C13: Proteção de dados pessoais | D13: Lei 13.709/2018 (LGPD), art. 55-A | E13: a conferir | F13: https://www.gov.br/anpd/pt-br | G13: HTTP 200 | H13: Natureza jurídica/enquadramento na Lei 13.848/2019 a conferir antes de comparar com as demais.

Sheet Roteiro
A1: Agência | B1: AIR_CAP | C1: AIR_MET | D1: AIR_PRO | E1: PS | F1: EST | G1: AGE | H1: PRO | I1: ARR_CAP | J1: ARR_MET | K1: ARR_PRO
A2: ANATEL | B2: buscar | C2: buscar | D2: buscar | E2: buscar | F2: buscar | G2: buscar | H2: buscar | I2: buscar | J2: buscar | K2: buscar
A3: ANVISA | B3: buscar | C3: buscar | D3: buscar | E3: buscar | F3: buscar | G3: buscar | H3: buscar | I3: buscar | J3: buscar | K3: buscar
A4: ANEEL | B4: buscar | C4: buscar | D4: buscar | E4: buscar | F4: buscar | G4: buscar | H4: buscar | I4: buscar | J4: buscar | K4: buscar
A5: ANTT | B5: buscar | C5: buscar | D5: buscar | E5: buscar | F5: buscar | G5: buscar | H5: buscar | I5: buscar | J5: buscar | K5: buscar
A6: ANAC | B6: buscar | C6: buscar | D6: buscar | E6: buscar | F6: buscar | G6: buscar | H6: buscar | I6: buscar | J6: buscar | K6: buscar
A7: ANTAQ | B7: buscar | C7: buscar | D7: buscar | E7: buscar | F7: buscar | G7: buscar | H7: buscar | I7: buscar | J7: buscar | K7: buscar
A8: ANP | B8: buscar | C8: buscar | D8: buscar | E8: buscar | F8: buscar | G8: buscar | H8: buscar | I8: buscar | J8: buscar | K8: buscar
A9: ANA | B9: buscar | C9: buscar | D9: buscar | E9: buscar | F9: buscar | G9: buscar | H9: buscar | I9: buscar | J9: buscar | K9: buscar
A10: ANS | B10: buscar | C10: buscar | D10: buscar | E10: buscar | F10: buscar | G10: buscar | H10: buscar | I10: buscar | J10: buscar | K10: buscar
A11: ANM | B11: buscar | C11: buscar | D11: buscar | E11: buscar | F11: buscar | G11: buscar | H11: buscar | I11: buscar | J11: buscar | K11: buscar
A12: ANCINE | B12: buscar | C12: buscar | D12: buscar | E12: buscar | F12: buscar | G12: buscar | H12: buscar | I12: buscar | J12: buscar | K12: buscar
A13: ANPD | B13: buscar | C13: buscar | D13: buscar | E13: buscar | F13: buscar | G13: buscar | H13: buscar | I13: buscar | J13: buscar | K13: buscar
A14: Cada link abre uma busca restrita ao portal da agência pelo 1º termo do critério (ver aba Critérios para os demais termos).

Sheet Avaliação
A1: Agência | B1: Condição ID | C1: Critério | D1: Dim. | E1: Nível | F1: Ordem | G1: Condição | H1: Resposta (SIM/NÃO/?) | I1: URL da evidência | J1: Data da consulta | K1: Status revisão | L1: Observação (sem dados pessoais) | M1: Conta estimado | N1: Conta comprovado
A2: ANATEL | B2: AIR_CAP.MC.I | C2: AIR_CAP | D2: 1 | E2: Melhoria Contínua | F2: I | G2: Plano de capacitação formalizado e em execução, incluindo permanente reciclagem em técnicas de AIR; | K2: pendente | M2: =IF(H2="SIM",1,0) | N2: =IF(AND(H2="SIM",K2="validado",I2<>""),1,0)
A3: ANATEL | B3: AIR_CAP.GER.I | C3: AIR_CAP | D3: 1 | E3: Gerenciado | F3: I | G3: Capacitações em AIR estão institucionalizadas, sem um plano formalizado; | K3: pendente | M3: =IF(H3="SIM",1,0) | N3: =IF(AND(H3="SIM",K3="validado",I3<>""),1,0)
A4: ANATEL | B4: AIR_CAP.INI.I | C4: AIR_CAP | D4: 1 | E4: Inicial | F4: I | G4: Capacitações em AIR não estão institucionalizadas; | K4: pendente | M4: =IF(H4="SIM",1,0) | N4: =IF(AND(H4="SIM",K4="validado",I4<>""),1,0)
A5: ANATEL | B5: AIR_CAP.MC.II | C5: AIR_CAP | D5: 1 | E5: Melhoria Contínua | F5: II | G5: no mínimo 75% dos servidores envolvidos em elaboração de regulação capacitados em nível intermediário, ou seja, capazes de desenvolver as etapas de mapeamento do problema (incluindo atores, objetivos e base legal), levantamento de alternativas, análises qualitativas dos impactos das alternativas e elaboração do plano de implementação da alternativa sugerida; | K5: pendente | M5: =IF(H5="SIM",1,0) | N5: =IF(AND(H5="SIM",K5="validado",I5<>""),1,0)
A6: ANATEL | B6: AIR_CAP.GER.II | C6: AIR_CAP | D6: 1 | E6: Gerenciado | F6: II | G6: no mínimo 75% dos servidores envolvidos em elaboração de regulação capacitados em nível básico, ou seja, capazes de reconhecer o objetivo de uma AIR, bem como nomear as etapas de uma AIR e possibilidades de dispensa e não aplicabilidade, nos termos no Decreto nº 10.411, de 2020; | K6: pendente | M6: =IF(H6="SIM",1,0) | N6: =IF(AND(H6="SIM",K6="validado",I6<>""),1,0)
A7: ANATEL | B7: AIR_CAP.INI.II | C7: AIR_CAP | D7: 1 | E7: Inicial | F7: II | G7: de 50% a 74% dos servidores envolvidos em elaboração de regulação capacitados em nível básico, ou seja, capazes de reconhecer o objetivo de uma AIR, bem como nomear as etapas de uma AIR e possibilidades de dispensa e não aplicabilidade, nos termos no Decreto nº 10.411, de 30 de junho de 2020; | K7: pendente | M7: =IF(H7="SIM",1,0) | N7: =IF(AND(H7="SIM",K7="validado",I7<>""),1,0)
A8: ANATEL | B8: AIR_CAP.MC.III | C8: AIR_CAP | D8: 1 | E8: Melhoria Contínua | F8: III | G8: no mínimo 50% dos servidores envolvidos em elaboração de regulação capacitados em nível avançado, ou seja, capazes de desenvolver as etapas de mapeamento do problema (incluindo atores, objetivos e base legal), levantamento de alternativas, análises qualitativas e quantitativas dos impactos das alternativas e elaboração do plano de implementação da alternativa sugerida (incluindo avaliação de riscos). | K8: pendente | M8: =IF(H8="SIM",1,0) | N8: =IF(AND(H8="SIM",K8="validado",I8<>""),1,0)
A9: ANATEL | B9: AIR_CAP.GER.III | C9: AIR_CAP | D9: 1 | E9: Gerenciado | F9: III | G9: de 50% a 74% dos servidores envolvidos em elaboração de regulação capacitados em nível intermediário, ou seja, capazes de desenvolver as etapas de mapeamento do problema (incluindo atores, objetivos e base legal), levantamento de alternativas, análises qualitativas dos impactos das alternativas e elaboração do plano de implementação da alternativa sugerida; | K9: pendente | M9: =IF(H9="SIM",1,0) | N9: =IF(AND(H9="SIM",K9="validado",I9<>""),1,0)
A10: ANATEL | B10: AIR_CAP.INI.III | C10: AIR_CAP | D10: 1 | E10: Inicial | F10: III | G10: de 25% a 49% dos servidores envolvidos em elaboração de regulação capacitados em nível intermediário, ou seja, capazes de desenvolver as etapas de mapeamento do problema (incluindo atores, objetivos e base legal), levantamento de alternativas, análises qualitativas dos impactos das alternativas e elaboração do plano de implementação da alternativa sugerida. | K10: pendente | M10: =IF(H10="SIM",1,0) | N10: =IF(AND(H10="SIM",K10="validado",I10<>""),1,0)
A11: ANATEL | B11: AIR_CAP.GER.IV | C11: AIR_CAP | D11: 1 | E11: Gerenciado | F11: IV | G11: de 25% a 49% dos servidores envolvidos em elaboração de regulação capacitados em nível avançado, ou seja, capazes de desenvolver as etapas de mapeamento do problema (incluindo atores, objetivos e base legal), levantamento de alternativas, análises qualitativas e quantitativas dos impactos das alternativas e elaboração do plano de implementação da alternativa sugerida (incluindo avaliação de riscos). | K11: pendente | M11: =IF(H11="SIM",1,0) | N11: =IF(AND(H11="SIM",K11="validado",I11<>""),1,0)
A12: ANATEL | B12: AIR_MET.MC.I | C12: AIR_MET | D12: 1 | E12: Melhoria Contínua | F12: I | G12: Critérios objetivos estabelecidos para classificação quanto ao nível de impacto e complexidade da AIR; | K12: pendente | M12: =IF(H12="SIM",1,0) | N12: =IF(AND(H12="SIM",K12="validado",I12<>""),1,0)
A13: ANATEL | B13: AIR_MET.GER.I | C13: AIR_MET | D13: 1 | E13: Gerenciado | F13: I | G13: Existência de manual ou ato normativo interno instituindo a aplicabilidade institucional da AIR; | K13: pendente | M13: =IF(H13="SIM",1,0) | N13: =IF(AND(H13="SIM",K13="validado",I13<>""),1,0)
... A877: ANPD | B877: ARR_PRO.INI.II | C877: ARR_PRO | D877: 6 | E877: Inicial | F877: II | G877: A agenda de ARR está publicada no site do órgão. | K877: pendente | M877: =IF(H877="SIM",1,0) | N877: =IF(AND(H877="SIM",K877="validado",I877<>""),1,0)

Sheet Cálculo
A1: Agência | B1: Critério | C1: Dim. | D1: Peso na dim. | E1: n Inicial | F1: n Gerenc. | G1: n MC | H1: ok Inicial (est) | I1: ok Gerenc. (est) | J1: ok MC (est) | K1: ok Inicial (comp) | L1: ok Gerenc. (comp) | M1: ok MC (comp) | N1: Classificação ESTIMADA (0–1) | O1: Classificação COMPROVADA (0–1)
A2: ANATEL | B2: AIR_CAP | C2: 1 | D2: 0.3 | E2: =COUNTIFS(Condições!$C$2:$C$74,$B2,Condições!$E$2:$E$74,"Inicial") | F2: =COUNTIFS(Condições!$C$2:$C$74,$B2,Condições!$E$2:$E$74,"Gerenciado") | G2: =COUNTIFS(Condições!$C$2:$C$74,$B2,Condições!$E$2:$E$74,"Melhoria Contínua") | H2: =COUNTIFS(Avaliação!$A$2:$A$877,$A2,Avaliação!$C$2:$C$877,$B2,Avaliação!$E$2:$E$877,"Inicial",Avaliação!$M$2:$M$877,1) | I2: =COUNTIFS(Avaliação!$A$2:$A$877,$A2,Avaliação!$C$2:$C$877,$B2,Avaliação!$E$2:$E$877,"Gerenciado",Avaliação!$M$2:$M$877,1) | J2: =COUNTIFS(Avaliação!$A$2:$A$877,$A2,Avaliação!$C$2:$C$877,$B2,Avaliação!$E$2:$E$877,"Melhoria Contínua",Avaliação!$M$2:$M$877,1) | K2: =COUNTIFS(Avaliação!$A$2:$A$877,$A2,Avaliação!$C$2:$C$877,$B2,Avaliação!$E$2:$E$877,"Inicial",Avaliação!$N$2:$N$877,1) | L2: =COUNTIFS(Avaliação!$A$2:$A$877,$A2,Avaliação!$C$2:$C$877,$B2,Avaliação!$E$2:$E$877,"Gerenciado",Avaliação!$N$2:$N$877,1) | M2: =COUNTIFS(Avaliação!$A$2:$A$877,$A2,Avaliação!$C$2:$C$877,$B2,Avaliação!$E$2:$E$877,"Melhoria Contínua",Avaliação!$N$2:$N$877,1) | N2: =IF(H2<E2,v_ini*H2/E2,IF(I2<F2,v_ini+(v_ger-v_ini)*I2/F2,IF(J2<G2,v_ger+(v_mc-v_ger)*J2/G2,v_mc))) | O2: =IF(K2<E2,v_ini*K2/E2,IF(L2<F2,v_ini+(v_ger-v_ini)*L2/F2,IF(M2<G2,v_ger+(v_mc-v_ger)*M2/G2,v_mc)))
A3: ANATEL | B3: AIR_MET | C3: 1 | D3: 0.35 | E3: =COUNTIFS(Condições!$C$2:$C$74,$B3,Condições!$E$2:$E$74,"Inicial") | F3: =COUNTIFS(Condições!$C$2:$C$74,$B3,Condições!$E$2:$E$74,"Gerenciado") | G3: =COUNTIFS(Condições!$C$2:$C$74,$B3,Condições!$E$2:$E$74,"Melhoria Contínua") | H3: =COUNTIFS(Avaliação!$A$2:$A$877,$A3,Avaliação!$C$2:$C$877,$B3,Avaliação!$E$2:$E$877,"Inicial",Avaliação!$M$2:$M$877,1) | I3: =COUNTIFS(Avaliação!$A$2:$A$877,$A3,Avaliação!$C$2:$C$877,$B3,Avaliação!$E$2:$E$877,"Gerenciado",Avaliação!$M$2:$M$877,1) | J3: =COUNTIFS(Avaliação!$A$2:$A$877,$A3,Avaliação!$C$2:$C$877,$B3,Avaliação!$E$2:$E$877,"Melhoria Contínua",Avaliação!$M$2:$M$877,1) | K3: =COUNTIFS(Avaliação!$A$2:$A$877,$A3,Avaliação!$C$2:$C$877,$B3,Avaliação!$E$2:$E$877,"Inicial",Avaliação!$N$2:$N$877,1) | L3: =COUNTIFS(Avaliação!$A$2:$A$877,$A3,Avaliação!$C$2:$C$877,$B3,Avaliação!$E$2:$E$877,"Gerenciado",Avaliação!$N$2:$N$877,1) | M3: =COUNTIFS(Avaliação!$A$2:$A$877,$A3,Avaliação!$C$2:$C$877,$B3,Avaliação!$E$2:$E$877,"Melhoria Contínua",Avaliação!$N$2:$N$877,1) | N3: =IF(H3<E3,v_ini*H3/E3,IF(I3<F3,v_ini+(v_ger-v_ini)*I3/F3,IF(J3<G3,v_ger+(v_mc-v_ger)*J3/G3,v_mc))) | O3: =IF(K3<E3,v_ini*K3/E3,IF(L3<F3,v_ini+(v_ger-v_ini)*L3/F3,IF(M3<G3,v_ger+(v_mc-v_ger)*M3/G3,v_mc)))
A4: ANATEL | B4: AIR_PRO | C4: 1 | D4: 0.35 | E4: =COUNTIFS(Condições!$C$2:$C$74,$B4,Condições!$E$2:$E$74,"Inicial") | F4: =COUNTIFS(Condições!$C$2:$C$74,$B4,Condições!$E$2:$E$74,"Gerenciado") | G4: =COUNTIFS(Condições!$C$2:$C$74,$B4,Condições!$E$2:$E$74,"Melhoria Contínua") | H4: =COUNTIFS(Avaliação!$A$2:$A$877,$A4,Avaliação!$C$2:$C$877,$B4,Avaliação!$E$2:$E$877,"Inicial",Avaliação!$M$2:$M$877,1) | I4: =COUNTIFS(Avaliação!$A$2:$A$877,$A4,Avaliação!$C$2:$C$877,$B4,Avaliação!$E$2:$E$877,"Gerenciado",Avaliação!$M$2:$M$877,1) | J4: =COUNTIFS(Avaliação!$A$2:$A$877,$A4,Avaliação!$C$2:$C$877,$B4,Avaliação!$E$2:$E$877,"Melhoria Contínua",Avaliação!$M$2:$M$877,1) | K4: =COUNTIFS(Avaliação!$A$2:$A$877,$A4,Avaliação!$C$2:$C$877,$B4,Avaliação!$E$2:$E$877,"Inicial",Avaliação!$N$2:$N$877,1) | L4: =COUNTIFS(Avaliação!$A$2:$A$877,$A4,Avaliação!$C$2:$C$877,$B4,Avaliação!$E$2:$E$877,"Gerenciado",Avaliação!$N$2:$N$877,1) | M4: =COUNTIFS(Avaliação!$A$2:$A$877,$A4,Avaliação!$C$2:$C$877,$B4,Avaliação!$E$2:$E$877,"Melhoria Contínua",Avaliação!$N$2:$N$877,1) | N4: =IF(H4<E4,v_ini*H4/E4,IF(I4<F4,v_ini+(v_ger-v_ini)*I4/F4,IF(J4<G4,v_ger+(v_mc-v_ger)*J4/G4,v_mc))) | O4: =IF(K4<E4,v_ini*K4/E4,IF(L4<F4,v_ini+(v_ger-v_ini)*L4/F4,IF(M4<G4,v_ger+(v_mc-v_ger)*M4/G4,v_mc)))
A5: ANATEL | B5: PS | C5: 2 | D5: 1 | E5: =COUNTIFS(Condições!$C$2:$C$74,$B5,Condições!$E$2:$E$74,"Inicial") | F5: =COUNTIFS(Condições!$C$2:$C$74,$B5,Condições!$E$2:$E$74,"Gerenciado") | G5: =COUNTIFS(Condições!$C$2:$C$74,$B5,Condições!$E$2:$E$74,"Melhoria Contínua") | H5: =COUNTIFS(Avaliação!$A$2:$A$877,$A5,Avaliação!$C$2:$C$877,$B5,Avaliação!$E$2:$E$877,"Inicial",Avaliação!$M$2:$M$877,1) | I5: =COUNTIFS(Avaliação!$A$2:$A$877,$A5,Avaliação!$C$2:$C$877,$B5,Avaliação!$E$2:$E$877,"Gerenciado",Avaliação!$M$2:$M$877,1) | J5: =COUNTIFS(Avaliação!$A$2:$A$877,$A5,Avaliação!$C$2:$C$877,$B5,Avaliação!$E$2:$E$877,"Melhoria Contínua",Avaliação!$M$2:$M$877,1) | K5: =COUNTIFS(Avaliação!$A$2:$A$877,$A5,Avaliação!$C$2:$C$877,$B5,Avaliação!$E$2:$E$877,"Inicial",Avaliação!$N$2:$N$877,1) | L5: =COUNTIFS(Avaliação!$A$2:$A$877,$A5,Avaliação!$C$2:$C$877,$B5,Avaliação!$E$2:$E$877,"Gerenciado",Avaliação!$N$2:$N$877,1) | M5: =COUNTIFS(Avaliação!$A$2:$A$877,$A5,Avaliação!$C$2:$C$877,$B5,Avaliação!$E$2:$E$877,"Melhoria Contínua",Avaliação!$N$2:$N$877,1) | N5: =IF(H5<E5,v_ini*H5/E5,IF(I5<F5,v_ini+(v_ger-v_ini)*I5/F5,IF(J5<G5,v_ger+(v_mc-v_ger)*J5/G5,v_mc))) | O5: =IF(K5<E5,v_ini*K5/E5,IF(L5<F5,v_ini+(v_ger-v_ini)*L5/F5,IF(M5<G5,v_ger+(v_mc-v_ger)*M5/G5,v_mc)))
A6: ANATEL | B6: EST | C6: 3 | D6: 1 | E6: =COUNTIFS(Condições!$C$2:$C$74,$B6,Condições!$E$2:$E$74,"Inicial") | F6: =COUNTIFS(Condições!$C$2:$C$74,$B6,Condições!$E$2:$E$74,"Gerenciado") | G6: =COUNTIFS(Condições!$C$2:$C$74,$B6,Condições!$E$2:$E$74,"Melhoria Contínua") | H6: =COUNTIFS(Avaliação!$A$2:$A$877,$A6,Avaliação!$C$2:$C$877,$B6,Avaliação!$E$2:$E$877,"Inicial",Avaliação!$M$2:$M$877,1) | I6: =COUNTIFS(Avaliação!$A$2:$A$877,$A6,Avaliação!$C$2:$C$877,$B6,Avaliação!$E$2:$E$877,"Gerenciado",Avaliação!$M$2:$M$877,1) | J6: =COUNTIFS(Avaliação!$A$2:$A$877,$A6,Avaliação!$C$2:$C$877,$B6,Avaliação!$E$2:$E$877,"Melhoria Contínua",Avaliação!$M$2:$M$877,1) | K6: =COUNTIFS(Avaliação!$A$2:$A$877,$A6,Avaliação!$C$2:$C$877,$B6,Avaliação!$E$2:$E$877,"Inicial",Avaliação!$N$2:$N$877,1) | L6: =COUNTIFS(Avaliação!$A$2:$A$877,$A6,Avaliação!$C$2:$C$877,$B6,Avaliação!$E$2:$E$877,"Gerenciado",Avaliação!$N$2:$N$877,1) | M6: =COUNTIFS(Avaliação!$A$2:$A$877,$A6,Avaliação!$C$2:$C$877,$B6,Avaliação!$E$2:$E$877,"Melhoria Contínua",Avaliação!$N$2:$N$877,1) | N6: =IF(H6<E6,v_ini*H6/E6,IF(I6<F6,v_ini+(v_ger-v_ini)*I6/F6,IF(J6<G6,v_ger+(v_mc-v_ger)*J6/G6,v_mc))) | O6: =IF(K6<E6,v_ini*K6/E6,IF(L6<F6,v_ini+(v_ger-v_ini)*L6/F6,IF(M6<G6,v_ger+(v_mc-v_ger)*M6/G6,v_mc)))
A7: ANATEL | B7: AGE | C7: 4 | D7: 1 | E7: =COUNTIFS(Condições!$C$2:$C$74,$B7,Condições!$E$2:$E$74,"Inicial") | F7: =COUNTIFS(Condições!$C$2:$C$74,$B7,Condições!$E$2:$E$74,"Gerenciado") | G7: =COUNTIFS(Condições!$C$2:$C$74,$B7,Condições!$E$2:$E$74,"Melhoria Contínua") | H7: =COUNTIFS(Avaliação!$A$2:$A$877,$A7,Avaliação!$C$2:$C$877,$B7,Avaliação!$E$2:$E$877,"Inicial",Avaliação!$M$2:$M$877,1) | I7: =COUNTIFS(Avaliação!$A$2:$A$877,$A7,Avaliação!$C$2:$C$877,$B7,Avaliação!$E$2:$E$877,"Gerenciado",Avaliação!$M$2:$M$877,1) | J7: =COUNTIFS(Avaliação!$A$2:$A$877,$A7,Avaliação!$C$2:$C$877,$B7,Avaliação!$E$2:$E$877,"Melhoria Contínua",Avaliação!$M$2:$M$877,1) | K7: =COUNTIFS(Avaliação!$A$2:$A$877,$A7,Avaliação!$C$2:$C$877,$B7,Avaliação!$E$2:$E$877,"Inicial",Avaliação!$N$2:$N$877,1) | L7: =COUNTIFS(Avaliação!$A$2:$A$877,$A7,Avaliação!$C$2:$C$877,$B7,Avaliação!$E$2:$E$877,"Gerenciado",Avaliação!$N$2:$N$877,1) | M7: =COUNTIFS(Avaliação!$A$2:$A$877,$A7,Avaliação!$C$2:$C$877,$B7,Avaliação!$E$2:$E$877,"Melhoria Contínua",Avaliação!$N$2:$N$877,1) | N7: =IF(H7<E7,v_ini*H7/E7,IF(I7<F7,v_ini+(v_ger-v_ini)*I7/F7,IF(J7<G7,v_ger+(v_mc-v_ger)*J7/G7,v_mc))) | O7: =IF(K7<E7,v_ini*K7/E7,IF(L7<F7,v_ini+(v_ger-v_ini)*L7/F7,IF(M7<G7,v_ger+(v_mc-v_ger)*M7/G7,v_mc)))
A8: ANATEL | B8: PRO | C8: 5 | D8: 1 | E8: =COUNTIFS(Condições!$C$2:$C$74,$B8,Condições!$E$2:$E$74,"Inicial") | F8: =COUNTIFS(Condições!$C$2:$C$74,$B8,Condições!$E$2:$E$74,"Gerenciado") | G8: =COUNTIFS(Condições!$C$2:$C$74,$B8,Condições!$E$2:$E$74,"Melhoria Contínua") | H8: =COUNTIFS(Avaliação!$A$2:$A$877,$A8,Avaliação!$C$2:$C$877,$B8,Avaliação!$E$2:$E$877,"Inicial",Avaliação!$M$2:$M$877,1) | I8: =COUNTIFS(Avaliação!$A$2:$A$877,$A8,Avaliação!$C$2:$C$877,$B8,Avaliação!$E$2:$E$877,"Gerenciado",Avaliação!$M$2:$M$877,1) | J8: =COUNTIFS(Avaliação!$A$2:$A$877,$A8,Avaliação!$C$2:$C$877,$B8,Avaliação!$E$2:$E$877,"Melhoria Contínua",Avaliação!$M$2:$M$877,1) | K8: =COUNTIFS(Avaliação!$A$2:$A$877,$A8,Avaliação!$C$2:$C$877,$B8,Avaliação!$E$2:$E$877,"Inicial",Avaliação!$N$2:$N$877,1) | L8: =COUNTIFS(Avaliação!$A$2:$A$877,$A8,Avaliação!$C$2:$C$877,$B8,Avaliação!$E$2:$E$877,"Gerenciado",Avaliação!$N$2:$N$877,1) | M8: =COUNTIFS(Avaliação!$A$2:$A$877,$A8,Avaliação!$C$2:$C$877,$B8,Avaliação!$E$2:$E$877,"Melhoria Contínua",Avaliação!$N$2:$N$877,1) | N8: =IF(H8<E8,v_ini*H8/E8,IF(I8<F8,v_ini+(v_ger-v_ini)*I8/F8,IF(J8<G8,v_ger+(v_mc-v_ger)*J8/G8,v_mc))) | O8: =IF(K8<E8,v_ini*K8/E8,IF(L8<F8,v_ini+(v_ger-v_ini)*L8/F8,IF(M8<G8,v_ger+(v_mc-v_ger)*M8/G8,v_mc)))
A9: ANATEL | B9: ARR_CAP | C9: 6 | D9: 0.3 | E9: =COUNTIFS(Condições!$C$2:$C$74,$B9,Condições!$E$2:$E$74,"Inicial") | F9: =COUNTIFS(Condições!$C$2:$C$74,$B9,Condições!$E$2:$E$74,"Gerenciado") | G9: =COUNTIFS(Condições!$C$2:$C$74,$B9,Condições!$E$2:$E$74,"Melhoria Contínua") | H9: =COUNTIFS(Avaliação!$A$2:$A$877,$A9,Avaliação!$C$2:$C$877,$B9,Avaliação!$E$2:$E$877,"Inicial",Avaliação!$M$2:$M$877,1) | I9: =COUNTIFS(Avaliação!$A$2:$A$877,$A9,Avaliação!$C$2:$C$877,$B9,Avaliação!$E$2:$E$877,"Gerenciado",Avaliação!$M$2:$M$877,1) | J9: =COUNTIFS(Avaliação!$A$2:$A$877,$A9,Avaliação!$C$2:$C$877,$B9,Avaliação!$E$2:$E$877,"Melhoria Contínua",Avaliação!$M$2:$M$877,1) | K9: =COUNTIFS(Avaliação!$A$2:$A$877,$A9,Avaliação!$C$2:$C$877,$B9,Avaliação!$E$2:$E$877,"Inicial",Avaliação!$N$2:$N$877,1) | L9: =COUNTIFS(Avaliação!$A$2:$A$877,$A9,Avaliação!$C$2:$C$877,$B9,Avaliação!$E$2:$E$877,"Gerenciado",Avaliação!$N$2:$N$877,1) | M9: =COUNTIFS(Avaliação!$A$2:$A$877,$A9,Avaliação!$C$2:$C$877,$B9,Avaliação!$E$2:$E$877,"Melhoria Contínua",Avaliação!$N$2:$N$877,1) | N9: =IF(H9<E9,v_ini*H9/E9,IF(I9<F9,v_ini+(v_ger-v_ini)*I9/F9,IF(J9<G9,v_ger+(v_mc-v_ger)*J9/G9,v_mc))) | O9: =IF(K9<E9,v_ini*K9/E9,IF(L9<F9,v_ini+(v_ger-v_ini)*L9/F9,IF(M9<G9,v_ger+(v_mc-v_ger)*M9/G9,v_mc)))
